Workbook
Name Oracle11i: 'Complexity and Scale'!$G$76:$G$78
Name OracleR12: 'Complexity and Scale'!$F$76
Name Other: 'Complexity and Scale'!$E$76:$E$78
Name SAP: 'Complexity and Scale'!$D$76:$D$78

Sheet Sumário
B6: Análise e posicionamento do Time de Conteúdo - Tax Research
C9: Compras/Entradas | G9: Premissas da Presente Análise
C10: Análise TR team | D10: NCMs
C11: NCMs existentes no conteúdo | D11: 2692 | G11: A presente análise está restrita as NCMs/linhas aqui informadas (inbound/outbound), sendo que operações específicas poderão não estar abrangidas pelo IDT;
C12: NCMs não existentes no conteúdo | D12: 164 | G12: O resultado da análise apresentado por meio do "Total Geral" refere-se a quantidade de linhas e não a quantidade de NCMs;
C13: NCMs inexistentes na TIPI vigente | D13: 14 | G13: NCMs não existentes no Conteúdo IDT referem-se a conteúdos que não estão incluídos na cobertura standard e poderão ser customizados;
C14: Operação atendida | D14: 4 | G14: Operação não atendida refere-se as operações (CFOPs informados) que não estão incluídos na cobertura stadard e poderão ser customizados;
C15: Operação não atendida | D15: 120 | G15: Para os serviços prestados, os municípios atendidos seguem a LC 116/03;
C16: Total Geral | D16: 2994 | G16: Análise exclusiva dos municípios aqui informados em conjunto com a UF também indicada pelo cliente (Lista municípios);
G17: Para os serviços tomados o sistema determina o responsável (prestador/tomador) pelo pagamento do imposto e não pelo local da retenção;
G18: Municípios atendidos estão disponíveis na sheet "Lista Municípios&Serviços - POR".
C19: Vendas/Saídas
C20: Análise TR team | D20: NCMs | G20: Operações passíveis de customização (Não Standard) - Exemplos:
C21: NCMs existentes no conteúdo | D21: 1126
C22: NCMs não existentes no conteúdo | D22: 123 | G22: Transferências de Saldo Credor
C23: NCMs inexistentes na TIPI vigente | D23: 10 | G23: Diferimento
C24: Operação atendida | D24: 6 | G24: Suspensão
C25: Operação não atendida | D25: 82 | G25: Antecipação
C26: Total Geral | D26: 1347 | G26: Armazém Geral
G27: Subcontratação (frete)
G28: Redespacho
C29: Serviços Prestados | G29: Regimes tributários: Regime Simples Nacional/MEI
C30: Análise TR team | D30: Municípios | G30: Industrialização em terceiros / Op. Triangulares
C31: Municípios atendidos | D31: 834 | G31: Transferência/Remessa
C32: Total Geral | D32: 834 | G32: Regimes especiais
C35: Serviços Tomados
C36: Análise TR team | D36: Municípios
C37: Municípios atendidos | D37: 834
C38: Total Geral | D38: 834

Sheet Geral
A1: ONESOURCE INDIRECT TAX DETERMINATION
A2: QUESTIONÁRIO MOTOR DE CÁLCULO
A3: FORMULÁRIO PARA MAPEAMENTO DE CENÁRIO FISCAL
A4: Nome do Responsável: | B4: Data do Preenchimento:
A5: Informe os dados das Empresas e Filiais a serem consideradas no Projeto | B5: Preencher os dados completos da aba Empresas
A6: Quais são os ramos de negócios das empresas? | B6: Informar os CNAEs (principais e secundários) na aba Empresas
A7: Qual é o Faturamento Anual consolidado das empresas? | B7: Informar o faturamento anual em R$ na aba Empresas
A8: Quais tipos de operações tributárias sua empresa realiza? | B8: Preencher os dados completos da aba CFOPS
A9: Qual é a quantidade de Produtos (SKUS) cadastrados na operação de Compras? | B9: Preencher os dados completos da aba Volumetria
A10: Qual é a quantidade de Produtos (SKUS) cadastrados na operação de Vendas? | B10: Preencher os dados completos da aba Volumetria
A11: Qual é a quantidade média de novos Produtos (SKUS) cadastrados por Mês? | B11: Preencher os dados completos da aba Volumetria
A12: Qual é a volumetria de documentos fiscais emitidos e recebidos? | B12: Preencher os dados completos da aba Volumetria
A13: Quantas NCMS existem na operação de Vendas? | B13: Preencher os dados completos da aba NCMS VENDAS
A14: Quantas NCMS existem na operação de Compras? | B14: Preencher os dados completos da aba NCMS COMPRAS
A15: Possui Regimes Especiais? | B15: Preencher os dados completos da aba Regimes Especiais
A16: Sistemas Utilizados | B16: Preencher os dados completos da aba Sistemas

Sheet Lista de Valores
B1: aba: Informações Gerais - POR
B2: Remessa para armazém geral
B3: Remessa para depósito fechado
B4: Transferência entre estabelecimentos
B5: Venda por conta e ordem de terceiros
B6: Industrialização efetuada para outra empresa
B7: Remessa para industrialização por encomenda (direta)
B8: Remessa para industrialização por encomenda por conta e ordem de terceiros
B9: Remessa para conserto
B10: Remessa para destruição
B11: Venda em consignação industrial
B12: Venda em consignação mercantil
... B46: APAC

Sheet Empresas
A1: ONESOURCE INDIRECT TAX DETERMINATION
A2: Preencher abaixo os CNPJs completo de todos os estabelecimentos da empresa
A3: CNPJ | B3: RAZÃO SOCIAL | C3: Matriz/Filial | D3: UF | E3: MUNICÍPIO | F3: SITUAÇÃO | G3: CNAE | H3: Emite Nota Mercantil? | I3: Recebe Nota Mercantil? | J3: Emite CTE? | K3: Recebe CTE? | L3: Emite Nota de Serviço? | M3: Recebe Nota de Serviço? | N3: Regime de Apuração? | O3: Faturamento Anual
A4: 07.080.388/0001-27 | B4: OLEOQUIMICA INDUSTRIA E COMERCIO DE PRODUTOS QUIMICOS LTDA | C4: Matriz | D4: BA | E4: CAMAÇARI | F4: Ativa | G4: 20.29-1-00 | H4: Sim | I4: Sim | J4: Não | K4: Sim | L4: Não | M4: Sim | N4: Lucro Real | O4: 1.6888769e+09
A5: 62.545.686/0001-53 | B5: OXITENO SA INDUSTRIA E COMERCIO | C5: Matriz | D5: SP | E5: SÃO PAULO | F5: Ativa | G5: 20.29-1-00 | H5: Sim | I5: Sim | J5: Não | K5: Sim | L5: Não | M5: Sim | N5: Lucro Real | O5: 0
A6: 62.545.686/0002-34 | B6: OXITENO SA INDUSTRIA E COMERCIO | C6: Filial | D6: SP | E6: MAUÁ | F6: Ativa | G6: 20.29-1-00 | H6: Sim | I6: Sim | J6: Não | K6: Sim | L6: Não | M6: Sim | N6: Lucro Real | O6: 1.0994251e+09
A7: 62.545.686/0011-25 | B7: OXITENO SA INDUSTRIA E COMERCIO | C7: Filial | D7: SP | E7: MAUÁ | F7: Ativa | G7: 20.29-1-00 | H7: Sim | I7: Sim | J7: Não | K7: Sim | L7: Não | M7: Sim | N7: Lucro Real | O7: 5.8131284e+08
A8: 62.545.686/0012-06 | B8: OXITENO SA INDUSTRIA E COMERCIO | C8: Filial | D8: SP | E8: TREMEMBÉ | F8: Ativa | G8: 20.29-1-00 | H8: Sim | I8: Sim | J8: Não | K8: Sim | L8: Não | M8: Sim | N8: Lucro Real | O8: 4.7649161e+08
A9: 62.545.686/0013-97 | B9: OXITENO SA INDUSTRIA E COMERCIO | C9: Filial | D9: SP | E9: SUZANO | F9: Ativa | G9: 20.29-1-00 | H9: Sim | I9: Sim | J9: Não | K9: Sim | L9: Não | M9: Sim | N9: Lucro Real | O9: 2.6762094e+08
A10: 62.545.686/0017-10 | B10: OXITENO SA INDUSTRIA E COMERCIO | C10: Filial | D10: SP | E10: GUARULHOS | F10: Ativa | G10: 46.84-2-99 | H10: Sim | I10: Sim | J10: Não | K10: Sim | L10: Não | M10: Sim | N10: Lucro Real | O10: 1.1282543e+09
A11: 62.545.686/0018-00 | B11: OXITENO SA INDUSTRIA E COMERCIO | C11: Filial | D11: RS | E11: TRIUNFO | F11: Ativa | G11: 20.29-1-00 | H11: Sim | I11: Sim | J11: Não | K11: Sim | L11: Não | M11: Sim | N11: Lucro Real | O11: 1.8811365e+08
A12: 62.545.686/0019-82 | B12: OXITENO SA INDUSTRIA E COMERCIO | C12: Filial | D12: BA | E12: CAMAÇARI | F12: Ativa | G12: 20.29-1-00 | H12: Sim | I12: Sim | J12: Não | K12: Sim | L12: Não | M12: Sim | N12: Lucro Real | O12: 3.0505902e+09
A13: 62.545.686/0020-16 | B13: OXITENO SA INDUSTRIA E COMERCIO | C13: Filial | D13: BA | E13: CAMAÇARI | F13: Ativa | G13: 20.29-1-00 | H13: Sim | I13: Sim | J13: Não | K13: Sim | L13: Não | M13: Sim | N13: Lucro Real | O13: 1.5618182e+08

Sheet Volumetria
A1: ONESOURCE INDIRECT TAX DETERMINATION
A2: Informar a Volumetria de Documentos Fiscais Consolidado para todas as empresas
A3: Documento Fiscal Eletrônico (Emitidos) | B3: Volumetria Anual | C3: Média de Itens por Nota
A4: Nota Fiscal Mercantil (NFE) Modelo 55 | B4: 61418 | C4: 1.147
A5: Conhecimento de Transporte (CTE) Modelo 57 | B5: 0 | C5: 0
A6: Conhecimento de Transporte (CTE) Modelo 67 | B6: 0 | C6: 0
A7: MDFe Modelo 58 | B7: 0 | C7: 0
A8: Nota Fiscal de Serviços Municipal (Preencher os dados completos da aba Municípios) | B8: 0 | C8: 0
A9: Cupom Fiscal (NFCE) Modelo 65 | B9: 0 | C9: 0
A10: Cupom Fiscal (ECF) | B10: 0 | C10: 0
A11: Cupom Fiscal (SAT) | B11: 0 | C11: 0
A12: Documento Fiscal Eletrônico (Recebidos) | B12: Volumetria Anual | C12: Média de Itens por Nota
A13: Nota Fiscal Mercantil (NFE) Modelo 55 | B13: 49778 | C13: 1.3
A14: Conhecimento de Transporte (CTE) Modelo 57 | B14: 51005 | C14: 1.3
A15: Conhecimento de Transporte (CTE) Modelo 67 | B15: 433 | C15: 1.3
A16: MDFe Modelo 58 | B16: 0 | C16: 0
A17: Nota Fiscal de Serviços Municipal (Preencher os dados completos da aba Municípios) | B17: 20371 | C17: 1.3
A18: Cupom Fiscal (NFCE) Modelo 65 | B18: 0 | C18: 0
A19: Cupom Fiscal (ECF) | B19: 0 | C19: 0
A20: Cupom Fiscal (SAT) | B20: 0 | C20: 0
A21: CONTA MENSAL DE SERVIÇOS DE AGUA E/OU ESGOTO - CMSAE | B21: 50 | C21: 1
A22: Nota Fiscal de Energia Elétrica Eletrônica (NF3E) Modelo 65 | B22: 24 | C22: 1
A23: Nota Fiscal Conta de Energia Elétrica, modelo 6 (NFCEE) | B23: 108 | C23: 1
A24: Informar a Volumetria do Cadastro de Produtos (SKUS) Consolidado para todas as empresas
A25: Cadastro de Produtos (SKUS) | B25: Operação de Compras | C25: Operação de Vendas
A26: Quantidade total de Produtos (SKUS) cadastrados para todas as empresas informadas | B26: 6779 | C26: 7803
A27: Quantidade média de novos Produtos (SKUS) cadastrados por mês para todas as empresas informadas | B27: 5 | C27: 5

Sheet CFOPS
A1: ONESOURCE INDIRECT TAX DETERMINATION
A2: Informar as CFOPS que precisam estar contemplados no projeto, incluindo operações de Entradas e Saídas
A3: CFOP de Entrada | B3: Descrição da Operação relacionada a CFOP de Entrada | C3: CFOP de Saída | D3: Descrição da Operação relacionada a CFOP de Saída
A4: 1.101 | B4: INDUSTRIALIZAÇÃO MP | C4: 5.101 | D4: VENDA INTERCIA PRODUÇÃO DO ESTABELECIMENTO
A5: 1.101 | B5: INSUMOS C/ BASE REDUZIDA | C5: 5.101 | D5: VENDA DE PRODUÇÃO DO ESTABELECIMENTO
A6: 1.101 | B6: INDUSTRIALIZAÇÃO INTERCIA MP | C6: 5.101 | D6: VENDA COM DIFERIMENTO
A7: 1.101 | B7: CMP INSUMOS ICMS DIFERIDO | C7: 5.101 | D7: VENDA DE SUB PRODUTO
A8: 1.101 | B8: ICMS - INDUSTRIALIZAÇÃO | C8: 5.101 | D8: COMPLEMENTO DE PRECO
A9: 1.101 | B9: COMPRA PARA INDUSTRIALIZAÇÃO SOB REGIME DRAWBACK MERCADO INTERNO | C9: 5.102 | D9: VENDA INTERCIA DE MERCADORIA ADQUIRIDA OU RECEBIDA DE TERCEIROS
A10: 1.102 | B10: COMERCIALIZAÇÃO INTERCIA | C10: 5.102 | D10: REVENDA DE MERCADORIA ADQ/RECEBIDA DE TERCEIROS
A11: 1.102 | B11: COMERCIALIZAÇÃO | C11: 5.102 | D11: REVENDA COM DIFERIMENTO
A12: 1.116 | B12: ENTREGA FUTURA | C12: 5.102 | D12: REVENDA COM ENTREGA DEPOSITO/ARMAZÉM
A13: 1.117 | B13: ENTREGA FUTURA | C13: 5.102 | D13: VENDA DE MERCADORIA ADQUIRIDA OU RECEBIDA DE TERCEIROS
A14: 1.122 | B14: COMPRA P/ INDUSTR MERC REMETIDA AO INDUSTRIALIZADOR PELO FORNECEDOR SEM TRANSITAR ESTABELECIMENTO ADQUIRENTE | C14: 5.102 | D14: REVENDA C/ BASE CALCULO REDUZIDA DE MERCADORIA ADQ 3º
... A150: 2.949 | B150: EMPRÉSTIMO DE INSUMOS INDL | C150: 7.949 | D150: REMESSA AMOSTRA P/ EXTERIOR
A151: 3.101 | B151: INDUSTRIALIZAÇÃO MP
A152: 3.101 | B152: ICMS - INDUSTRIALIZAÇÃO
A153: 3.102 | B153: COMERCIALIZAÇÃO
A154: 3.102 | B154: IMPORTAÇÃO P/ REVENDA_x000D_
A155: 3.127 | B155: COMPRA PARA INDUSTRIALIZAÇÃO SOB REGIME DRAWBACK
A156: 3.201 | B156: DE PRODUÇÃO DO ESTABELECIMENTO ENVIADA PARA O EXTERIOR
A157: 3.201 | B157: RECUSA DE MERCADORIA NÃO ENTREGUE - VENDA
A158: 3.551 | B158: ATIVO IMOBILIZADO
A159: 3.556 | B159: USO OU CONSUMO
A160: 3.949 | B160: REM FRACIONADA CMP NORMAL/IMP
A161: 3.949 | B161: AMOSTRA GRÁTIS
A162: 3.949 | B162: REMESSAS FINANCEIRAS
... A164: 3.949 | B164: TESTE INDL

Sheet NCMS COMPRAS
A1: ONESOURCE INDIRECT TAX DETERMINATION
A2: Preencher os NCMS vinculados aos convênios aplicáveis que precisam estar contemplados no projeto, incluindo NCMS de devoluções de Ativo e ou Material de Uso ou Consumo mais recorrentes
A3: NCM | B3: CONVÊNIO APLICÁVEL | C3: CEST | D3: EXCEÇÃO TIPI
A4: 0101.29.00
A5: 0102.90.90
A6: 0305.20.90
A7: 0401.20.10
A8: 0402.21.10
A9: 0402.29.10
A10: 0402.99.00
A11: 0501.00.00
A12: 0601.20.00
A13: 0602.90.89
A14: 0602.90.90
A15: 0901.21.00
... A24: 1512.29.90
A25: 1513.29.19 | B25: LC 228/2026 REIQ | D25: Redução de alíquotas de PIS/Cofins para insumos químicos conforme LC 228/2026 (REIQ) ¿ válida mar/dez 2026.
A26: 1515.21.00
A27: 1515.30.00
A28: 1516.20.00
A29: 1517.90.90
A30: 1518.00.10
A31: 1520.00.10
A32: 1602.50.00
A33: 1701.99.00
A34: 1702.30.11
A35: 1702.30.20
A36: 1702.40.20
A37: 1702.50.00
... A201: 2901.10.00
A202: 2901.21.00 | B202: Lei 11.668/2023 | D202: Alíquotas PIS (1,65%) e COFINS (7,6%) na compra de ETENO da Braskem.
A203: 2901.29.00
A204: 2902.11.00
A205: 2902.30.00
A206: 2902.42.00
A207: 2902.50.00
A208: 2902.60.00
A209: 2902.90.20
A210: 2902.90.90
A211: 2903.11.10
...

Sheet NCMS VENDAS
A1: ONESOURCE INDIRECT TAX DETERMINATION
A2: Preencher os NCMS vinculados aos convênios aplicáveis que precisam estar contemplados no projeto, incluindo NCMS de devoluções de Ativo e ou Material de Uso ou Consumo mais recorrentes
A3: NCM | B3: CONVÊNIO APLICÁVEL | C3: CEST | D3: EXCEÇÃO TIPI
A4: 29053100 | B4: ICMS: ART 266, INC IX DECR 13780/12 (a) - TERMO DE ACORDO 3333/09 E PARECER 23388/17 CONV ICMS 159/08 - PRORROGADO PELO CONV 178/21 - 26/10/2021
A5: 73101090 | B5: ICMS: ART 286, INC XVI DO DECRETO 13.780 DE 16/03/2012 (RICMS-BA)
A6: 34029019 | B6: ICMS: ART 286, INC XX DO DECRETO 13.780 DE 16/03/2012 (RICMS-BA)
A7: 73101090 | B7: ICMS: ARTIGO 265, INC. XXX, ALINEA A (CONV.ICMS 88/91)DEC. 13780/2012
A8: 73110000 | B8: ICMS: ARTIGO 265, INC. XXX, ALINEA A (CONV.ICMS 88/91)DEC. 13780/2012
A9: 15153000 | B9: ICMS: ARTIGO 280 INCISO I DECRETO 13780/2012
A10: 27101931 | B10: ICMS: ARTIGO 280 INCISO I DECRETO 13780/2012
A11: 34042010 | B11: ICMS: ARTIGO 280 INCISO I DECRETO 13780/2012
A12: 38249929 | B12: ICMS: ARTIGO 280 INCISO I DECRETO 13780/2012
A13: 38249989 | B13: ICMS: ARTIGO 280 INCISO I DECRETO 13780/2012
A14: 84138100 | B14: ICMS: ARTIGO 7º, INCISO IX DO RICMS/2000-SP
A15: 84433299 | B15: ICMS: ARTIGO 7º, INCISO IX DO RICMS/2000-SP
... A1165: 39069069 | B1165: 06PIS-COFINS: ALIQUOTA 0 P/ PIS/COFINS CONF. ART. 1 INCISOS 1 E 2 LEI 10925/04. PROD.EXCLUSIVO P/ DEFENSIVOS AGROPECUÁRIOS, FERTILIZANTES E ADUBOS

Sheet Municípios
A1: ONESOURCE INDIRECT TAX DETERMINATION
A2: Informar a Volumetria Anual de Notas de Serviços por Município
A3: UF | B3: Municipio | C3: CodServico | D3: Subitem | E3: Quantidade de Notas (Serviços Tomados) | F3: Quantidade de Notas (Serviços Prestados)
A4: SP | B4: SAO JOSE DOS CAMPOS | C4: 1602 | D4: 16.02 | E4: 812 | F4: 0
A5: SP | B5: SANTOS | C5: 2001 | D5: 20.01 | E5: 725 | F5: 0
A6: BA | B6: SALVADOR | C6: 20.01 | D6: 20.01 | E6: 554 | F6: 0
A7: SP | B7: GUARULHOS | C7: 1602 | D7: 16.02 | E7: 496 | F7: 0
A8: SP | B8: BARUERI | C8: 17.05 | D8: 17.05 | E8: 419 | F8: 0
A9: SP | B9: SANTOS | C9: 20.01 | D9: 20.01 | E9: 403 | F9: 0
A10: BA | B10: CAMACARI | C10: 1602 | D10: 16.02 | E10: 377 | F10: 0
A11: SP | B11: SANTOS | C11: 11.04. | D11: 11.04 | E11: 326 | F11: 0
A12: SP | B12: SANTOS | C12: 33.01 | D12: 33.01 | E12: 326 | F12: 0
A13: BA | B13: CAMACARI | C13: 1401 | D13: 14.01 | E13: 309 | F13: 0
A14: BA | B14: SALVADOR | C14: 33.01 | D14: 33.01 | E14: 261 | F14: 0
A15: SP | B15: SAO PAULO | C15: 7.02 | D15: 7.02 | E15: 260 | F15: 0
A16: SP | B16: SAO PAULO | C16: 702 | D16: 7.02 | E16: 245 | F16: 0
A17: BA | B17: SALVADOR | C17: 3301 | D17: 33.01 | E17: 240 | F17: 0
A18: SP | B18: SAO PAULO | C18: 2692 | D18: 1.04 | E18: 239 | F18: 0
A19: SP | B19: SAO PAULO | C19: 2919 | D19: 1.07 | E19: 166 | F19: 0
A20: SP | B20: SANTOS | C20: 17.09 | D20: 17.09 | E20: 163 | F20: 0
A21: BA | B21: CANDEIAS | C21: 17.09 | D21: 17.09 | E21: 162 | F21: 0
A22: SP | B22: DIADEMA | C22: 16.02 | D22: 16.02 | E22: 162 | F22: 0
A23: SP | B23: SAO PAULO | C23: 2660 | D23: 1.01 | E23: 156 | F23: 0
A24: SP | B24: SAO PAULO | C24: 3980 | D24: 17.01 | E24: 156 | F24: 0
A25: SP | B25: SAO PAULO | C25: 17.01 | D25: 17.01 | E25: 154 | F25: 0
A26: SP | B26: GUARUJA | C26: 2001 | D26: 20.01 | E26: 145 | F26: 0
A27: SP | B27: SAO PAULO | C27: 6530 | D27: 17.13 | E27: 144 | F27: 0
A28: BA | B28: DIAS D'AVILA | C28: 1401 | D28: 14.01 | E28: 142 | F28: 0
A29: BA | B29: CAMACARI | C29: 702 | D29: 7.02 | E29: 138 | F29: 0
A30: SP | B30: SAO PAULO | C30: 2881 | D30: 1.06 | E30: 133 | F30: 0
A31: BA | B31: SALVADOR | C31: 1401 | D31: 14.01 | E31: 131 | F31: 0
A32: SP | B32: SANTOS | C32: 1104 | D32: 11.04 | E32: 129 | F32: 0
A33: SP | B33: SAO PAULO | C33: 14.01.14 | D33: 14.01 | E33: 126 | F33: 0
A34: SP | B34: SAO PAULO | C34: 6491 | D34: 17.05 | E34: 124 | F34: 0
A35: SP | B35: SAO PAULO | C35: 17.05 | D35: 17.05 | E35: 117 | F35: 0
A36: SP | B36: SAO PAULO | C36: 1401 | D36: 14.01 | E36: 116 | F36: 0
A37: BA | B37: CANDEIAS | C37: 11.04 | D37: 11.04 | E37: 111 | F37: 0
A38: SP | B38: SAO JOSE DOS CAMPOS | C38: 1401 | D38: 14.01 | E38: 110 | F38: 0
A39: SP | B39: SAO PAULO | C39: 2800 | D39: 1.05 | E39: 107 | F39: 0
A40: SP | B40: SAO PAULO | C40: 26.01 | D40: 26.01 | E40: 105 | F40: 0
...

Sheet Regimes Especiais
A1: ONESOURCE INDIRECT TAX DETERMINATION
A2: LISTAR REGIMES ESPECIAIS (Quando houver)
A3: UF | B3: PEDIDO Nº | C3: OBJETO/TERMO REGIME ESPECIAL | D3: OBSERVAÇÕES
A4: SP | B4: 19991/2016 | C4: artigo 327-J do RICMS | D4: 051Diferido ICMS - Diferimento 100% do ICMS devido na saída interna, conf Regime Especial nº 19991/2016, nos termos do artigo 327-J do RICMS
A5: SP | B5: 015122/2016 | D5: 051DIFERIDO - REGIME ESPECIAL CONFORME PROCESSO 015122/2016
A6: SP | B6: 36614/2019 | C6: ART 327-J e 489 RICMS, DEC. 45490/2000 - II ART 1º PORT CAT 43/07 | D6: 051Diferido ICMS - DIFERIMENTO 100% ICMS CFE REG. ESPECIAL Nº36614/2019, NOS TERMOS ART 327-J e 489 RICMS, DEC. 45490/2000 - II ART 1º PORT CAT 43/07
A7: SP | B7: 22665/2017 | C7: TERMOS ART. 327-J RICMS | D7: 051Diferido ICMS - DIFERIMENTO DE 100% DO ICMS DEVIDO NA SAÍDA INTERNA, REGIME ESPECIAL Nº 22665/2017, NOS TERMOS ART. 327-J RICMS
A8: SP | B8: 029185/2018 | C8: ART 327-J e 489 RICMS, DEC.45490/00 E ART. 13-A DA PORT.CAT 18/21 | D8: 051Diferido ICMS - DIFERIMENTO 100% ICMS CFE REG. ESPEC. Nº029185/2018, NOS TERMOS ART 327-J e 489 RICMS, DEC.45490/00 E ART. 13-A DA PORT.CAT 18/21
A9: SP | B9: 2434/2015 | C9: art. 327-J e 489 do Dec 45.490/2000 RICMS/SP. | D9: 051Diferido ICMS 100% - Conf REGESP 2434/2015 - art. 327-J e 489 do Dec 45.490/2000 RICMS/SP.

Sheet Sistemas
A1: ONESOURCE INDIRECT TAX DETERMINATION
A2: ARQUITETURA DE SISTEMAS
A3: PEGUNTA | B3: RESPOSTA
A4: Qual(is) o(s) seu(s) sistema(s) a integrar com o TAX DETERMINATION? | B4: Oracle R11
A5: Especifique a respectiva versão, incluindo informação do último patch; para SAP ECC por exemplo, indicar EHP e SP | B5: Oracle EBS 11.5.10.2
A6: Qual o número de instâncias produtivas? | B6: 1
A7: Indique o tipo de integração: Batch(DFI), SOAP ou REST (Exceto para SAP e Oracle que possuem conectores nativos) | B7: DBLINK / Conectores nativos
A8: Agregar outras informações que considerar relevante para o projeto | B8: N/a

Sheet Brazil Est
C2: ONESOURCE IMPLEMENTATION ESTIMATING CALCULATOR (Brazil Sole Source) | L2: Template Guideline - Comments, Notes
C4: General Criteria | D4: Scope Input | E4: Factor | H4: Scale Criteria | I4: Scale Input | J4: Factor | L4: This Estimating Template is for High - Level and Detail Estimates for ONESOURCE Indirect Tax solesource implementations. Note SUT Compliance - Will need to contact MasterSAF for estimating Fiscal Compliance Note - This template can be for implementations that include Premium Content or Custom Built Content Note - This template is not for Partner Led implementations Note - This template provides only an estimate for a Premium Content offering, a more accurate estimate can only provided with further analysis of the customer's transactions and applicable tax regimes. © Copyright 2013 Thomson Reuters Indirect Tax, All Rights Reserved. COMPANY CONFIDENTIAL
C5: ERP System | D5: =IF(#REF!="SAP","SAP",IF(#REF!="Oracle 11i","Oracle 11i",IF(#REF!="Oracle R12","Oracle R12","Other"))) -> #REF! | E5: =IF(D5="","-",VLOOKUP(D5,ERP[],2,FALSE)) -> #REF! | H5: Total Branches | I5: =IF(Geral!B5<10,"<10",IF(Geral!B5<26,"10-25",">25")) -> >25 | J5: =IFERROR(VLOOKUP(I5,Branch[],2,FALSE),"") -> 2
C6: Operation Types | D6: =IF(Geral!#REF!="Produtos","Goods",IF(Geral!#REF!="Serviços","Service","Both")) -> #REF! | E6: =IF(D6="","-",VLOOKUP(D6,Type[],2,FALSE)) -> #REF! | H6: State Registrations | I6: =IF(Geral!B6<9,"<9 States",IF(Geral!B6<19,"9-18 States",">18 States")) -> >18 States | J6: =IFERROR(VLOOKUP(I6,States[],2,FALSE),"") -> 2
C7: Process Scope (OTC, PTP) | D7: =IF(Geral!#REF!="Compras","PTP",IF(Geral!#REF!="Vendas","OTC","Both")) -> #REF! | E7: =IF(D7="","-",VLOOKUP(D7,Scope[],2,FALSE)) -> #REF! | H7: # of NCMs | I7: =IF(Geral!#REF!<100,"<100",IF(Geral!#REF!<251,"100-250",IF(Geral!#REF!<401,"250-400",IF(Geral!#REF!<701,"400-700",IF(Geral!#REF!<1001,"700-1000",">1000"))))) -> #REF! | J7: =IFERROR(VLOOKUP(I7,NCM[],2,FALSE),"")
C8: Supply Chain Location | D8: =IF(Geral!#REF!="Varejo","Retail",IF(Geral!#REF!="Indústria/Importador","Manufacturer/Importer",IF(Geral!#REF!="Distribuidor","Wholesale/Distributer","Multiple"))) -> #REF! | E8: =IF(D8="","-",VLOOKUP(D8,Chain[],2,FALSE)) -> #REF! | H8: Sales - # of lines | I8: =IF(#REF!="","N/A",IF(#REF!<10,"<10",IF(#REF!<21,"10-20",IF(#REF!<31,"20-30",IF(#REF!<41,"30-40",IF(#REF!<51,"40-50",">50")))))) -> #REF! | J8: =IFERROR(VLOOKUP(I8,Sales_NumberOfLines[],2,FALSE),"")
C9: Content | D9: Premium + | E9: =IF(D9="","-",VLOOKUP(D9,Content[],2,FALSE)) -> 2 | H9: Purchases - # of lines | I9: =IF(Empresas!#REF!="","N/A",IF(Empresas!#REF!<10,"<10",IF(Empresas!#REF!<21,"10-20",IF(Empresas!#REF!<31,"20-30",IF(Empresas!#REF!<41,"30-40",IF(Empresas!#REF!<51,"40-50",">50")))))) -> #REF! | J9: =IFERROR(VLOOKUP(I9,Purchases_NumberOfLines[],2,FALSE),"")
C10: Architecture | D10: =IF(#REF!="Própria","Standard",IF(#REF!="Datacenter Thomson Reuters","Hosted TRTA",)) -> #REF! | E10: - | H10: Sales - Withholding Taxes | I10: =IF('Formulas and Lists'!K33=0,"N/A",IF('Formulas and Lists'!K33=1,"1",IF('Formulas and Lists'!K33=2,"2",">2"))) -> >2 | J10: =IFERROR(VLOOKUP(I10,Sales_Taxes_Wth[],2,FALSE),"") -> 2
C11: Project Timeline (Months) | D11: =IF('Complexity and Scale'!F34<200,6,IF('Complexity and Scale'!F34<400,9,12)) -> #REF! | E11: - | H11: Purchases - Withholding Taxes | I11: =IF('Formulas and Lists'!K25=0,"N/A",IF('Formulas and Lists'!K25=1,"1",IF('Formulas and Lists'!K25=2,"2",">2"))) -> N/A | J11: =IFERROR(VLOOKUP(I11,Purchase_Taxes_Wth[],2,FALSE),"") -> 0
C12: Testing | D12: =IF('Complexity and Scale'!F34<200,"Standard",IF('Complexity and Scale'!F34<400,"Extended","On-Site")) -> #REF! | E12: -
C13: Go-Live Support | D13: =IF('Complexity and Scale'!F34<200,"Standard Hypercare",IF('Complexity and Scale'!F34<400,"Extended Hypercare","On-Site Hypercare")) -> #REF! | E13: -
C14: Training Included | D14: Yes | E14: =IF(D14="","-",VLOOKUP(D14,Ed[],2,FALSE)) -> - | H14: Content Criteria | I14: Scope Input | J14: Factor
C15: Implementation Model | D15: =IF(Geral!B12="Thomson Reuters","Sole Source","Partner-Led") -> Partner-Led | E15: - | H15: ICMS-ST - Sales - Ship-From States | I15: =IF(#REF!<2,"N/A",IF(#REF!<9,"<9 States",IF(#REF!<19,"9-18 States",">18 States"))) -> #REF! | J15: =IFERROR(VLOOKUP(I15,ICMSST_Sales_ShipFromStates[],2,FALSE),"")
H16: ICMS-ST - Sales - Ship-To States | I16: =IF(#REF!<2,"N/A",IF(#REF!<9,"<9 States",IF(#REF!<19,"9-18 States",">18 States"))) -> #REF! | J16: =IFERROR(VLOOKUP(I16,ICMSST_Sales_ShipToStates[],2,FALSE),"")
H17: ICMS-ST - Purchases - Ship-From States | I17: =IF(#REF!<2,"N/A",IF(#REF!<9,"<9 States",IF(#REF!<19,"9-18 States",">18 States"))) -> #REF! | J17: =IFERROR(VLOOKUP(I17,ICMSST_Purchases_ShipFromStates[],2,FALSE),"")
H18: ICMS-ST - Purchases - Ship-To States | I18: =IF(#REF!<2,"N/A",IF(#REF!<9,"<9 States",IF(#REF!<19,"9-18 States",">18 States"))) -> #REF! | J18: =IFERROR(VLOOKUP(I18,ICMSST_Purchases_ShipToStates[],2,FALSE),"")
H19: ICMS-ST - # of NCMs | I19: =IF(#REF!+#REF!<100,"<100",IF(#REF!+#REF!<251,"100-250",IF(#REF!+#REF!<401,"250-400",IF(#REF!+#REF!<701,"400-700",IF(#REF!+#REF!<1001,"700-1000",">1000"))))) -> #REF! | J19: =IFERROR(VLOOKUP(I19,ICMSST_NCM[],2,FALSE),"")
H20: ISS - # of Municipalities | I20: =IF(#REF!=0,"N/A",IF(#REF!<100,"<100",IF(#REF!<251,"100-250",IF(#REF!<401,"250-400",IF(#REF!<701,"400-700",IF(#REF!<1001,"700-1000",">1000")))))) -> #REF! | J20: =IFERROR(VLOOKUP(I20,ISS_Municipalities[],2,FALSE),"")
H21: ISS - Service Codes | I21: =IF(#REF!=0,"N/A",IF(#REF!<9,"<9 codes",IF(#REF!<19,"9-18 codes",">18 codes"))) -> #REF! | J21: =IFERROR(VLOOKUP(I21,ISS_ServiceCodes[],2,FALSE),"")
H25: Bill Rate | I25: 125
D27: Estimated Hours | H27: Estimated Fees
C28: High Level - Estimate Summary | D28: =IF(D40<460,"Incomplete",D40) -> #REF! | H28: =IF(D28="Incomplete",D28,H40) -> #REF!
C30: Level 1 - Estimate Summary | D30: Total | E30: PS
B31: 1 | C31: ONESOURCE Kickoff, Guidance and Control | D31: ='Complexity and Scale'!F30 -> #REF! | E31: =+D31 -> #REF! | H31: =IFERROR(D31*$I$25,"-") -> -
B32: 2 | C32: ONESOURCE Technical Requirements, Architecture & Performance | D32: ='Complexity and Scale'!F31 -> #REF! | E32: =+D32 -> #REF! | H32: =IFERROR(D32*$I$25,"-") -> -
B33: 3 | C33: ONESOURCE Functional Requirements | D33: =IFERROR('Complexity and Scale'!F32,"-") -> - | E33: =+D33 -> - | H33: =IFERROR(D33*$I$25,"-") -> -
B34: 4 | C34: =IF(D10='Complexity and Scale'!L4,"ONESOURCE Software Install & Setup (Standard)",(IF(D10='Complexity and Scale'!L5,"ONESOURCE Software Install & Setup (Advanced)","ONESOURCE Software Install & Setup (TRTA Hosted)"))) -> #REF! | D34: =IFERROR('Complexity and Scale'!F33,"-") -> - | E34: =+D34 -> - | H34: =IFERROR(D34*$I$25,"-") -> -
B35: 5 | C35: ONESOURCE Configuration & ERP Integration | D35: =IFERROR(IF(D15="Sole Source",'Complexity and Scale'!F34,'Complexity and Scale'!H34),"-") -> - | E35: =+D35 -> - | H35: =IFERROR(D35*$I$25,"-") -> -
B36: 6 | C36: Fiscal Operations and Use Case Definition Requirements | D36: ='Complexity and Scale'!F35 -> 40 | E36: =+D36 -> 40 | H36: =IFERROR(D36*$I$25,"-") -> 5000
B37: 7 | C37: =CONCATENATE("ONESOURCE Content ","- ",D9) -> ONESOURCE Content - Premium + | E37: - | H37: =IFERROR(D37*$I$25,"-") -> 0
B38: 8 | C38: ONESOURCE Testing, UAT and Tax Determination Scenarios | D38: =IFERROR('Complexity and Scale'!F37,"-") -> - | E38: =+D38 -> - | H38: =IFERROR(D38*$I$25,"-") -> -
B39: 9 | C39: ONESOURCE Production Readiness, Go Live, Stabilization | D39: =IFERROR('Complexity and Scale'!F38,"-") -> - | E39: =+D39 -> - | H39: =IFERROR(D39*$I$25,"-") -> -
C40: Total ONESOURCE Implementation Services | D40: =SUM(D31:D39) -> #REF! | E40: =SUM(E31:E39) -> #REF! | H40: =IFERROR(D40*$I$25,"-") -> -
B42: TCO - ONESOURCE Determination Implementation & Training Services
C43: Consulting and Training Fees | D43: Estimated Hours | H43: Cost
B44: 1 | C44: ONESOURCE Consulting Implementation Services | D44: =D40 -> #REF! | H44: =+D44*125 -> #REF!
B45: 2 | C45: ONESOURCE Determination Onsite Training (up to 6 attendees) | D45: =IF(D14="Yes","Flat Fee","-") -> Flat Fee | H45: 6000
B46: 3 | C46: ONSOURCE Determination ERP Integration Training | D46: =IF(D14="Yes","Flat Fee","-") -> Flat Fee | H46: 6000
B47: 4 | C47: =IF($D$9='Complexity and Scale'!$J$5,CONCATENATE('Brazil Est'!$C$37," (Initial Build)"),(IF(D9='Complexity and Scale'!J6,CONCATENATE('Brazil Est'!C37," (Content Training)"),"-"))) -> ONESOURCE Content - Premium + (Content Training) | D47: =IF($D$9='Complexity and Scale'!$J$4,"-","Flat Fee") -> Flat Fee | E47: =IF(F9='Complexity and Scale'!T5,'Brazil Est'!E36,"-") -> - | H47: 28800
B48: 5 | C48: =IF($D$9='Complexity and Scale'!$J$5,CONCATENATE('Brazil Est'!$C$37," (Annual Maintenance)"),(IF(D10='Complexity and Scale'!J7,CONCATENATE('Brazil Est'!C38," (Content Training)"),"-"))) -> #REF! | D48: =IF($D$9='Complexity and Scale'!$J$5,"Flat Fee","-") -> - | E48: =IF(F10='Complexity and Scale'!T6,'Brazil Est'!E37,"-") -> - | H48: 0
...

Sheet General Information - ENG
A2: Filing Date | F2: Responsible Name
A4: Corporate Information
A5: How many companies (headquarters/branches) will be implemented in this project? | F5: 999
A6: How many brazilian states are the companies placed? | F6: 27
AA9: Warehouse shipment of goods
AA10: Company goods transfer
AA11: Shipping, leasing and loans
AA12: Third-party sales
AA13: Repair shipment of goods
AA14: Manufacturing shipment of goods
AA15: Destruction shipment of goods
A19: Questions | F19: Answers
A20: What are the main activities of your company, based on Brazilian regulation? Ex: import, manufacturer, reseller, services provider, etc.
A21: Which option is going to be the implementation model?
A22: Does your company mantain stock? (warehouses, distribution centers, etc.) If so, which states?
A23: Does your company during sales or purchase process can be considered as industry?
A24: How many products (NCM codes) do apply to your business for Sales and Purchase simultaneously?
A25: Choose the specific operations that your company work:
A26: When does your company want to implement ONESOURCE Indirect Tax Determination? Ex: 3 months after contract signature.
A27: Which business processes would you like to implement ONESOURCE Indirect Tax Determination?
A28: Is the Tax Calculation going to be needed for Goods and/or Services?
A29: What is the company role in supply chain management?

Sheet Purchase - ENG
A2: Purchase
A3: Questions | F3: Answers
A4: Please provide a list of all NCM codes that your company purchase. Go to NCM List Purchase Tab.
A5: Which suppliers do your company have? Ex: import, manufacturers, distributors, taxpayers, "simples nacional".
A6: Which states are your suppliers located? Ex: AP, RJ, SP, etc.
A7: Which states are the items purchased from? Ex: AP, RJ, SP, etc.
A8: Does your company purchase any goods subjected to ICMS Tax Substituition (ICMS-ST)? If yes, please inform if the role is "substitute taxpayer" or "replaced taxpayer".
A9: Does your company purchase goods from suppliers located in a free trade zone area? Ex: Manaus
A10: Does your company buy any goods subjected to a fiscal benefit? Ex: tax base reduction, exemption calculation, etc.
A11: Is there a special regime that applies to your purchase operations? Which?
A12: Does your company have import operations? If so, for which countries?
A13: How many purchase orders are submitted monthly?
A14: What is the average number of lines in purchase orders?
A15: Please provide a list of all the services that your company retains. Go to NCM List Purchase Tab.
... A18: Which taxes does the company have withholding taxes?

Sheet Sales - ENG
A2: Sales
A3: Questions | F3: Answers
A4: Please provide a list of all NCM codes that your company sell. Go to NCM List Sales Tab.
A5: Which customers do your company have? Ex: resellers, retailers, final users, etc.
A6: Which states are your customers located? Ex: AP, RJ, SP, etc.
A7: Which states are the items sold to? Ex: AP, RJ, SP, etc.
A8: Does your company sell any goods subjected to ICMS Tax Substituition (ICMS-ST)? If yes, please inform if the role is "substitute taxpayer" or "replaced taxpayer".
A9: Does your company sell goods from suppliers located in a free trade zone area? Ex: Manaus
A10: Does your company sell any goods subjected to a fiscal benefit? Please, provide all NCMs in NCM List Sales Tab. Ex: tax base reduction, exemption calculation, etc.
A11: Is there a special regime that applies to your sales operations? Which?
A12: Does your company have export operations? If so, for which countries?
A13: How many sales orders are submitted monthly?
A14: What is the average number of lines in sales orders?
A15: Please provide a list of all the services that your company provide. Go to NCM List Sales Tab.
... A18: Which taxes does the company have withholding taxes?

Sheet Determination
B3: ID | C3: Activity / Task Description | D3: TRTA Hours | F3: Deliverables | G3: Considerations
B4: 1 | C4: ='Brazil Est'!C31 -> ONESOURCE Kickoff, Guidance and Control | D4: ='Brazil Est'!D31 -> #REF! | F4: D.1 | G4: Gerenciamento do projeto
C5: Support overall project planning and financial reporting | G5: Acompanhamento das atividades/envolvimento do cliente
C6: ONESOURCE Issue, documentation, deployment & resource management | G6: Controle de atualizações/versões do produto
C7: Advise regarding best practices, risk management | G7: Reuniões tecnicas e funcionais
B8: 2 | C8: ='Brazil Est'!C32 -> ONESOURCE Technical Requirements, Architecture & Performance | D8: ='Brazil Est'!D32 -> #REF! | F8: D.2, D.3 | G8: Análise do servidor do cliente
C9: Review and define platform technical requirements | G9: Análise de voolumetria
C10: Review and Assess Architecture, Performance & Capacity per txn volumes | G10: Anállise técnica/arquitetura
B11: 3 | C11: ONESOURCE Functional Requirements | D11: ='Brazil Est'!D33 -> - | F11: D.4, D.5 | G11: Documentação funcional
C12: Identify, define, and document ONESOURCE Integration data-mapping | G12: Documentação técnica
C13: Identify, define, and document Company, Legal Entity and Registration Requirements | G13: Controle de versões de documentos
C14: Identify, define, and document Functional, Process & Data Requirements
B15: 4 | C15: ='Brazil Est'!C34 -> #REF! | D15: ='Brazil Est'!D34 -> - | G15: Instalação feita pela Thomson Reuters
C16: Install ONESOURCE Determination and Load Tax Content
C17: Install ONESOURCE Reports and ONESOURCE ERP Integration
B18: 5 | C18: ='Brazil Est'!C35 -> ONESOURCE Configuration & ERP Integration | D18: ='Brazil Est'!D35 -> - | F18: D.6
C19: Build ONESOURCE Integration | G19: Setup integração ERP com Tax Engine
C20: Company Registrations, Legal Entity Setup | G20: ICMS-ST 27 estados para 25% dos produtos
C21: ONESOURCE Determination Configuration (Trans Editors, Reference lists, Products etc.) | G21: Regimes especiais, operações de entrada, Difal, base reduzida,etc
C22: Allocations, Rates, Rules, Authority Configuration | G22: Regras para 1700 municipios
B23: 6 | C23: ='Brazil Est'!C36 -> Fiscal Operations and Use Case Definition Requirements | D23: ='Brazil Est'!D36 -> 40 | F23: D.7
C24: Identify and Define Fiscal Operations, Use Cases | G24: Cenários fiscais serão fornecidos pelo cliente
C25: Create and Document Fiscal Operations, Use Case Scenarios and Plan
B26: 7 | C26: ='Brazil Est'!C37 -> ONESOURCE Content - Premium + | F26: D.8
C27: Identify, define, and document potential Standard Content gaps
B28: 8 | C28: ='Brazil Est'!C38 -> ONESOURCE Testing, UAT and Tax Determination Scenarios | D28: ='Brazil Est'!D38 -> - | F28: D.9 | G28: Teste das regras e alíquotas
C29: Assist with Integration, Configuration Troubleshooting and Testing | G29: Teste de todos os regimes especiais
C30: Assist with Test Results and system integration tests | G30: Teste de todos os cenários de entrada e/ou saídas
B31: 9 | C31: ='Brazil Est'!C39 -> ONESOURCE Production Readiness, Go Live, Stabilization | D31: ='Brazil Est'!D39 -> - | F31: D.10 | G31: Acompanhamento Go-live para os cenários testados
C32: Planning and Production Cutover
C33: Hypercare & Stabilization
C34: Totals | D34: =SUM(D4:D4:D23)+SUM(D28:D31) -> #REF!
C37: Projeto Thomson Reuters | D37: Hours | E37: Rate | F37: Total USD | G37: Total BRL
B38: 1 | C38: ='Brazil Est'!C44 -> ONESOURCE Consulting Implementation Services | D38: =+D34 -> #REF! | E38: 125 | F38: =+D38*E38 -> #REF! | G38: =+F38*3.2 -> #REF!
B39: 2 | C39: ='Brazil Est'!C45 -> ONESOURCE Determination Onsite Training (up to 6 attendees) | D39: ='Brazil Est'!D45:E45 -> Flat Fee | F39: 6000 | G39: =+F39*3.2 -> 19200
B40: 3 | C40: ='Brazil Est'!C46 -> ONSOURCE Determination ERP Integration Training | D40: ='Brazil Est'!D46:E46 -> Flat Fee | F40: 6000 | G40: =+F40*3.2 -> 19200
B41: 4 | C41: Premium Content ICMS-ST | D41: =D26 -> 0 | E41: 100 | F41: =+D41*E41 -> 0 | G41: =+F41*3.2 -> 0
B42: 5 | C42: Horas Parceiro | D42: 0 | F42: 0 | G42: =+F42*3.2 -> 0
B43: 6 | C43: Total | D43: =SUM(D38,D41,D42) -> #REF! | F43: =SUM(F38:F42) -> #REF! | G43: =SUM(G38:G42) -> #REF!

Sheet Complexity and Scale
B2: Scope
B3: ERP | C3: Factor | D3: Operation Types | E3: Factor | F3: Process Scope | G3: Factor | H3: Supply Chain Location | I3: Factor | J3: Content | K3: Factor | L3: Archetecture | M3: Factor | N3: Project Duration | O3: Factor | P3: Testing | Q3: Hours | R3: Support | S3: Hours | T3: Training Included | U3: Factor | V3: Implementation Model | W3: Hours
B4: SAP | C4: 1 | D4: Goods | E4: 1 | F4: OTC | G4: 1 | H4: Retail | I4: 1 | J4: Standard | K4: 1 | L4: Standard | M4: 80 | N4: 6 | O4: 1 | P4: Standard | Q4: 150 | R4: Standard Hypercare | S4: 40 | T4: Yes | U4: - | V4: Partner-Led | W4: 40
B5: Oracle R12 | C5: 1.2 | D5: Service | E5: 1 | F5: PTP | G5: 1.25 | H5: Manufacturer/Importer | I5: 1.5 | J5: Premium | K5: 1.5 | L5: Advanced | M5: 80 | N5: 9 | O5: 1.5 | P5: Extended | Q5: 220 | R5: Extended Hypercare | S5: 80 | T5: No | U5: - | V5: Sole Source | W5: 120
B6: Oracle 11i | C6: 1.2 | D6: Both | E6: 1.5 | F6: Both | G6: 1.5 | H6: Wholesale/Distributer | I6: 1.5 | J6: Premium + | K6: 2 | L6: Hosted TRTA | M6: 80 | N6: 12 | O6: 2 | P6: On-Site | Q6: 400 | R6: On-Site Hypercare | S6: 120
B7: Other | C7: 1.5 | H7: Multiple | I7: 2
A9: Min | C9: =MIN(ERP[Factor]) -> 1 | E9: =MIN(Type[Factor]) -> 1 | G9: =MIN(Scope[Factor]) -> 1 | I9: =MIN(Chain[Factor]) -> 1 | K9: =MIN(Content[Factor]) -> 1 | M9: =SUM(C9:K9) -> 5
A10: Max | C10: =MAX(ERP[Factor]) -> 1.5 | E10: =MAX(Type[Factor]) -> 1.5 | G10: =MAX(Scope[Factor]) -> 1.5 | I10: =MAX(Chain[Factor]) -> 2 | K10: =MAX(Content[Factor]) -> 2 | M10: =SUM(C10:K10) -> 8.5
B11: Scale
B12: Total Branches | C12: Factor | D12: States | E12: Factor | F12: NCM classifications | G12: Factor | H12: Sales - # of Lines | I12: Factor | J12: Purchases - # of Lines | K12: Factor | L12: Purchase - Wth Taxes | M12: Factor | N12: Sales - Wth Taxes | O12: Factor | P12: Sales - Ship-From ICMS-ST States | Q12: Factor | R12: Sales - Ship-To ICMS-ST States Implementation | S12: Factor | T12: Purchases - Ship-From ICMS-ST States | U12: Factor | V12: Purchases - Ship-To ICMS-ST States Implementation | W12: Factor | X12: ICMS-ST - # of NCMs | Y12: Factor | Z12: Number of Municipalities | AA12: Factor | AB12: Service Codes | AC12: Factor
B13: <10 | C13: 1 | D13: <9 States | E13: 1 | F13: <100 | G13: 1 | H13: N/A | I13: 0 | J13: N/A | K13: 0 | L13: N/A | M13: 0 | N13: N/A | O13: 0 | P13: N/A | Q13: 0 | R13: N/A | S13: 0 | T13: N/A | U13: 0 | V13: N/A | W13: 0 | X13: <100 | Y13: 1 | Z13: N/A | AA13: 0 | AB13: N/A | AC13: 0
B14: 10-25 | C14: 1.5 | D14: 9-18 States | E14: 1.5 | F14: 100-250 | G14: 1.15 | H14: <10 | I14: 1 | J14: <10 | K14: 1 | L14: 1 | M14: 1 | N14: 1 | O14: 1 | P14: <9 States | Q14: 1.2 | R14: <9 States | S14: 1.2 | T14: <9 States | U14: 1.2 | V14: <9 States | W14: 1.2 | X14: 100-250 | Y14: 1.15 | Z14: <100 | AA14: 1 | AB14: <9 codes | AC14: 1.2
B15: >25 | C15: 2 | D15: >18 States | E15: 2 | F15: 250-400 | G15: 1.3 | H15: 10-20 | I15: 1.15 | J15: 10-20 | K15: 1.15 | L15: 2 | M15: 1,5 | N15: 2 | O15: 1,5 | P15: 9-18 States | Q15: 1.6 | R15: 9-18 States | S15: 1.6 | T15: 9-18 States | U15: 1.6 | V15: 9-18 States | W15: 1.6 | X15: 250-400 | Y15: 1.3 | Z15: 100-250 | AA15: 1.15 | AB15: 9-18 codes | AC15: 1.6
F16: 400-700 | G16: 1.5 | H16: 20-30 | I16: 1.3 | J16: 20-30 | K16: 1.3 | L16: >2 | M16: 2 | N16: >2 | O16: 2 | P16: >18 States | Q16: 2 | R16: >18 States | S16: 2 | T16: >18 States | U16: 2 | V16: >18 States | W16: 2 | X16: 400-700 | Y16: 1.5 | Z16: 250-400 | AA16: 1.3 | AB16: >18 codes | AC16: 2
F17: 700-1000 | G17: 1.75 | H17: 30-40 | I17: 1.5 | J17: 30-40 | K17: 1.5 | X17: 700-1000 | Y17: 1.75 | Z17: 400-700 | AA17: 1.5
F18: >1000 | G18: 2 | H18: 40-50 | I18: 1.75 | J18: 40-50 | K18: 1.75 | X18: >1000 | Y18: 2 | Z18: 700-1000 | AA18: 1.75
H19: >50 | I19: 2 | J19: >50 | K19: 2 | Z19: >1000 | AA19: 2
A22: Min | C22: =MIN(Branch[Factor]) -> 1 | E22: =MIN(States[Factor]) -> 1 | G22: =MIN(NCM[Factor]) -> 1 | I22: 0 | K22: 0 | M22: 0 | O22: 0 | Q22: =MIN(ICMSST_Sales_ShipFromStates[Factor]) -> 0 | S22: =MIN(ICMSST_Sales_ShipToStates[Factor]) -> 0 | U22: 0 | W22: 0 | Y22: =MIN(ICMSST_NCM[Factor]) -> 1 | AA22: =MIN(ISS_Municipalities[Factor]) -> 0 | AC22: =MIN(ISS_ServiceCodes[Factor]) -> 0
A23: Max | C23: =MAX(Branch[Factor]) -> 2 | E23: =MAX(States[Factor]) -> 2 | G23: =MAX(NCM[Factor]) -> 2 | I23: =MAX(Sales_NumberOfLines[Factor]) -> 2 | K23: =MAX(Purchases_NumberOfLines[Factor]) -> 2 | M23: 2 | O23: 2 | Q23: 2 | S23: 2 | U23: 2 | W23: 2 | Y23: =MAX(ICMSST_NCM[Factor]) -> 2 | AA23: =MAX(ISS_Municipalities[Factor]) -> 2 | AC23: =MAX(ISS_ServiceCodes[Factor]) -> 2
F26: Complexity | G26: Scale | H26: Combo | J26: =SUM(C22:ZZ22) -> 4 | K26: Factors | L26: Bill Rate
F27: =SUM('Brazil Est'!E5:E15) -> #REF! | G27: =(SUM('Brazil Est'!J5:J25)) -> 4 | H27: =G27*F27 -> #REF! | J27: =SUM(C23:ZZ23) -> 28 | K27: Low | L27: 100
F28: =IF(1+(3-1)*((F27-J28)/(K28-J28))>0,1+(3-1)*((F27-J28)/(K28-J28)),0) -> #REF! | H28: =IF(1+(6-1)*((H27-J30)/(K30-J30))>0,1+(6-1)*((H27-J30)/(K30-J30)),0) -> #REF! | I28: Complexity | J28: =M9 -> 5 | K28: =M10 -> 8.5 | L28: 125
C29: Activities - Standard Content | D29: Base | E29: Weight | F29: Estimate | I29: Scale | J29: =J26 -> 4 | K29: =J27 -> 28 | L29: 150
B30: 1 | C30: ='Brazil Est'!C31 -> ONESOURCE Kickoff, Guidance and Control | D30: 60 | F30: =('Brazil Est'!D11*20) -> #REF! | G30: 60 | J30: =J29*J28 -> 20 | K30: =K29*K28 -> 238
B31: 2 | C31: ='Brazil Est'!C32 -> ONESOURCE Technical Requirements, Architecture & Performance | D31: 20 | F31: =IF(F30=60,20,40) -> #REF! | G31: 20
B32: 3 | C32: ='Brazil Est'!C33 -> ONESOURCE Functional Requirements | D32: 60 | F32: =ROUNDDOWN(D32*$H$28,-1) -> #REF! | G32: 60
B33: 4 | C33: ='Brazil Est'!C34 -> #REF! | D33: 60 | F33: =VLOOKUP('Brazil Est'!D10,Host[],2,FALSE) -> #REF! | G33: 60 | H33: 0 | L33: =1.6/1 -> 1.6
B34: 5 | C34: ='Brazil Est'!C35 -> ONESOURCE Configuration & ERP Integration | D34: 120 | F34: =ROUND(D34*$H$28,-1) -> #REF! | G34: 160 | H34: =ROUND(F34*35%,-1) -> #REF! | I34: =E30/F27 -> #REF!
B35: 6 | C35: ='Brazil Est'!C36 -> Fiscal Operations and Use Case Definition Requirements | D35: 40 | F35: =VLOOKUP('Brazil Est'!D15,Implementation_Model[],2,FALSE) -> 40 | G35: 40 | I35: =2.5*1.6 -> 4
B36: 7 | C36: ='Brazil Est'!C37 -> ONESOURCE Content - Premium + | D36: Annex | F36: - | I36: =G32/H27 -> #REF!
B37: 8 | C37: ='Brazil Est'!C38 -> ONESOURCE Testing, UAT and Tax Determination Scenarios | D37: 60 | F37: =VLOOKUP('Brazil Est'!D12,Test[],2,FALSE) -> #REF! | G37: 60 | P37: =25/79.5 -> 0.31446541
B38: 9 | C38: ='Brazil Est'!C39 -> ONESOURCE Production Readiness, Go Live, Stabilization | D38: 40 | F38: =VLOOKUP('Brazil Est'!D13,Support[],2,FALSE) -> #REF! | G38: 40
D39: =SUM(D30:D38) -> 460 | F39: =SUM(F30:F38) -> #REF! | G39: =SUM(G30:G38) -> 500
C42: Training Services | D42: Price
B43: 1 | C43: ONESOURCE Determination Onsite Training (up to 6 attendees) | D43: 10000
B44: 2 | C44: ORA Integration Onsite Training (up to 6 attendees) | D44: 6500
B45: 3 | C45: SAP Integration Onsite Training (up to 6 attendees) | D45: 6500
B46: 4 | C46: Content Development Training | D46: 10000
C49: Premium Content Estimator Feed
C50: NCM Estimator | H50: Pass Through
...

Sheet Formulas and Lists
A1: ONESOURCE Functional Requirements | K1: Informações Gerais - POR | L1: General Information - ENG
A2: =1+(6-1)*(((B4*B5)-25)/(104.5-25)) -> 5.3081761 | K2: Qual será o modelo de implementação? (Comercial) | L2: Which option is going to be the implementation model?
A3: =ROUNDDOWN(60*A2,-1) -> 310 | K3: Thomson Reuters | L3: Thomson Reuters
A4: Scale Criteria (soma) - máximo 11 | B4: 11 | D4: =SUM(B4:B5) -> 19.5 | K4: Thomson Reuters e Parceiro (Consultoria) | L4: Thomson Reuters and Partner (Consulting)
A5: General Criteria(soma) - máximo 8,5 | B5: 8.5 | K5: Para quais os processos de negócio você gostaria de implementar a solução ONESOURCE Indirect Tax Determination? | L5: Which business processes would you like to implement ONESOURCE Indirect Tax Determination?
K6: Compras | L6: Purchases
A7: ONESOURCE Configuration & ERP Integration | K7: Vendas | L7: Sales
A8: =1+(6-1)*(((B10*B11)-25)/(104.5-25)) -> 5.3081761 | K8: Compras e Vendas | L8: Purchases and Sales
A9: =ROUND(120*A8,-1) -> 640 | K9: O cálculo de impostos será necessário para produtos e/ou serviços? | L9: Is the Tax Calculation going to be needed for Goods and/or Services?
A10: Scale Criteria (soma) - máximo 11 | B10: 11 | D10: =SUM(B10:B11) -> 19.5 | K10: Produtos | L10: Goods
A11: General Criteria(soma) - máximo 8,5 | B11: 8.5 | K11: Serviços | L11: Services
G12: Level 1 - Estimate Summary | H12: Formula | I12: Possible Values | K12: Produtos e Serviços | L12: Goods and Services
G13: ONESOURCE Kickoff, Guidance and Control | H13: Project Timeline (Months)*20 | I13: 120/180/240 | K13: Qual o papel da sua empresa na cadeia de suprimentos? | L13: What is the company role in supply chain management?
G14: ONESOURCE Technical Requirements, Architecture & Performance | I14: 40 | K14: Varejo | L14: Retail
G15: ONESOURCE Functional Requirements | H15: Sum of General Criteria and Scale Criteria Factors 1 | I15: 60-310 | K15: Indústria/Importador | L15: Manufacturer/Importer
G16: ONESOURCE Software Install & Setup | I16: 80 | K16: Distribuidor | L16: Wholesale/Distributer
G17: ONESOURCE Configuration & ERP Integration | H17: Sum of General Criteria and Scale Criteria Factors 2 / if Implementation Model = Partner-Led = Hours * 35% | I17: 120-640 | K17: Múltiplos | L17: Multiple
G18: Fiscal Operations and Use Case Definition Requirements | H18: Partner-Led = 40 / Sole Source = 120 | I18: 40/120 | K18: Compras - POR | L18: Purchase - ENG
G19: ONESOURCE Content | H19: Premium Content Estimator | K19: Sua empresa possui impostos com Retenções? Se sim, quais? | L19: Which taxes does the company have withholding taxes?
G20: ONESOURCE Testing, UAT and Tax Determination Scenarios | H20: Based on Project Timeline (Months) = 6 - Standard (150) / 9 - Extended (220) / 12 - On-Site (400) | I20: 150/220/400 | K20: FALSE | L20: TRUE
G21: ONESOURCE Production Readiness, Go Live, Stabilization | H21: Based on Project Timeline (Months) = 6 - Standard Hypercare (40) / 9 - Extended Hypercare (80) 12 - On-Site Hypercare (120) | I21: 40/80/120 | K21: FALSE | L21: TRUE
K22: FALSE | L22: TRUE
K23: FALSE | L23: TRUE
A24: Sum of General Criteria and Scale Criteria Factors 1 | B24: Possible Values | D24: Sum of General Criteria and Scale Criteria Factors 2 | E24: Possible Values | G24: Requirements x Estimator | K24: FALSE | L24: TRUE
A25: 10-10,5 | B25: 60 | D25: 10-10,5 | E25: 120 | G25: Informações Gerais / Quantas empresas (matriz/filial) serão implementadas neste projeto? | H25: Scale Criteria / Total Branches | K25: =COUNTIF('Formulas and Lists'!K20:K24,"VERDADEIRO") -> 0 | L25: =COUNTIF('Formulas and Lists'!L20:L24,"VERDADEIRO") -> 0
A26: 10,55-11 | B26: 70 | E26: 130 | G26: Informações Gerais / Quantos estados as empresas estão localizadas? | H26: Scale Criteria / State Registrations | K26: Vendas - POR | L26: Sales - ENG
A27: 11,05-11,45 | B27: 80 | E27: 140 | G27: Informações Gerais / Qual será o modelo de implementação? (Comercial) | H27: Scale Criteria / Implementation Model | K27: Sua empresa possui impostos com Retenções? Se sim, quais? | L27: Which taxes does the company have withholding taxes?
A28: 11,5-11,9 | B28: 90 | E28: 150 | G28: Informações Gerais / Para quais os processos de negócio você gostaria de implementar a solução ONESOURCE Indirect Tax Determination? | H28: General Criteria / Process Scope | K28: TRUE | L28: TRUE
A29: 11,95-12,35 | B29: 100 | E29: 160 | G29: Informações Gerais / O cálculo de impostos será necessário para produtos e/ou serviços? | H29: General Criteria / Operation Type | K29: TRUE | L29: TRUE
A30: 12,4-12,8 | B30: 110 | E30: 170 | G30: Informações Gerais / Qual o papel da sua empresa na cadeia de suprimentos? | H30: General Criteria / Supply Chain Location | K30: TRUE | L30: TRUE
A31: 12,85-13,2 | B31: 120 | E31: 180 | G31: Informações Gerais / Quantos códigos NCM aplicam-se ao seu negócio tanto para Vendas como para Compras? | H31: General Criteria / # of NCMs | K31: TRUE | L31: TRUE
A32: 13,25-13,55 | B32: 130 | E32: 190 | G32: Compras - POR / Sua empresa possui impostos com Retenções? Se sim, quais? | H32: Scale Criteria / Purchases - Withholding Taxes | K32: FALSE | L32: TRUE
A33: 13,6-13,95 | B33: 140 | E33: 200 | G33: Vendas - POR / Sua empresa possui impostos com Retenções? Se sim, quais? | H33: Scale Criteria / Sales - Withholding Taxes | K33: =COUNTIF('Formulas and Lists'!K28:K32,"VERDADEIRO") -> 4 | L33: =COUNTIF('Formulas and Lists'!L28:L32,"VERDADEIRO") -> 0
A34: 14-14,35 | B34: 150 | E34: 210 | G34: Compras - POR / Qual o número médio de linhas nos Pedidos de Compra? | H34: Scale Criteria / Purchases - # of lines | K34: Informações Técnicas - POR | L34: Informações Técnicas - POR
A35: 14,4-14,7 | B35: 160 | E35: 220 | G35: Vendas - POR / Qual o número médio de linhas nos Pedidos de Compra? | H35: Scale Criteria / Sales - # of lines | K35: Sistema de Origem | L35: Sistema de Origem
A36: 14,75-15,05 | B36: 170 | E36: 230 | G36: Informações Técnicas - POR / Sistema de Origem | H36: General Criteria / ERP System | K36: SAP | L36: SAP
A37: 15,1-15,4 | B37: 180 | E37: 240 | K37: Oracle 11i | L37: Oracle 11i
A38: 15,45-15,75 | B38: 190 | E38: 250 | K38: Oracle R12 | L38: Oracle R12
A39: 15,8-16,05 | B39: 200 | E39: 260 | K39: Outro | L39: Outro
A40: 16,1-16,4 | B40: 210 | E40: 270 | K40: Infraestrutura | L40: Infraestrutura
...

Sheet Premium Content Estimator
A1: Brazil ICMS-ST Project Calculator
A3: Data Feed
B4: Low | C4: High
A5: Number of NCM Codes | B5: 0
A6: Applicable States | B6: 1
A7: Grouping Factor | B7: 2
A11: Estimated Hours
A12: Premium Content Analysis and Design | B12: ='Complexity and Scale'!K63 -> 0
A13: Premium Content Legal Research | B13: ='Complexity and Scale'!$K$81*B7*'Complexity and Scale'!K69 -> 0
A14: Premium Contnet Sytem Entry | B14: =B6*'Complexity and Scale'!K74 -> 0
A15: Premium Content SSAE-16 Review | B15: =B7*B6*B5*'Complexity and Scale'!I75 -> 0
A16: Total Project Hours | B16: =ROUND(SUM(B12:B15),0) -> 0
A19: Hour Price | B19: 100
A20: Estimated Cost | B20: =B19*B16 -> 0
A22: Content Implementation
A23: Product Segments for ICMS-ST | B23: Factor | G23: Municipalities
A24: 10 - Materiais de Construção e Congêneres | B24: 1 | G24: Existing Content Municipalities | H24: Factor | J24: Existing Content Municipalities | K24: Factor
A25: 12 - Materiais Elétricos | B25: 1 | G25: if exists actual list (324) | H25: 1 | J25: Acailandia
A26: 21 - Produtos Eletrônicos, Eletroeletrônicos e Eletrodomésticos | B26: 1 | G26: if not in content | H26: 2 | J26: Alagoinhas
A27: 24 - Tintas e Vernizes | B27: 1 | J27: Alegrete
A28: 01 - Autopeças | B28: 1.5 | J28: Almeirim
A29: 04 - Cigarros e outros Produtos Derivados do fumo | B29: 1.5 | J29: Altamira
A30: 05 - Cimentos | B30: 1.5 | J30: Alvorada
A31: 06 - Combustíveis e Lubrificantes | B31: 1.5 | J31: Americana
A32: 07 - Energia Elétrica | B32: 1.5 | J32: Amparo SP
A33: 08 - Ferramentas | B33: 1.5 | J33: Ananindeua
A34: 09 - Lâmpadas, Reatores e "Starter" | B34: 1.5 | J34: Anapolis
A35: 11 - Materiais de Limpeza | B35: 1.5 | J35: Anchieta
A36: 14- Papeis, plasticos, produtos ceramicos e vidros | B36: 1.5 | J36: Angra dos Reis
A37: 16 - Pneumáticos, Câmaras de ar e Protetores de Borracha | B37: 1.5 | J37: Aparecida de Goiania
A38: 17 - Produtos Alimentícios | B38: 1.5 | J38: Aparecida do Taboado
... A48: 13 - Medicamentos de uso humano e outros produtos farmacêuticos para uso humano ou veterinário | B48: 2 | J48: Artur Nogueira
J49: Aruja
J50: Atibaia
J51: Bacabal
J52: Bage
J53: Balneario Camboriu
J54: Barbacena
J55: Barcarena
J56: Barreiras
...

Sheet Fiscosoft
A1: Consultor | B1: Qte. | C1: Min. p/NCM | D1: Min. | E1: Total min. | F1: Qte. UF | G1: Qte. NCM por UF | H1: Total NCM | I1: Minutos | J1: Horas | K1: Dias | L1: Meses
A2: Sênior | B2: 5 | C2: 15 | D2: 75 | E2: 75 | F2: 27 | G2: 500 | H2: 13500 | I2: 40500 | J2: 675 | K2: 84.38 | L2: 4.02
A3: Júnior | B3: 0 | C3: 21 | D3: 0
A4: Total | B4: 5 | D4: Média | E4: 15 | J4: 60 | K4: 8 | L4: 21
A6: Salário médio c/ encargos | C6: Total mês | D6: Custo total
A7: Consutor Sênior | B7: 8900 | C7: 44500 | D7: 178794.64
A8: Consutor Júnior | B8: 4600 | C8: 0
C9: 44500

Sheet Definitions
A1: Premium Content Analysis and Design
A2: In this stage, we review the NCMs that the prospect provide and determining if they are grouped together in certain areas of the TIPI. For example, if a company provides 200 NCMs but they are primarily all in one chapter of the TIPI then based on our research we have found that the incentives will be in Conventions, Protocols and Legislations that are close together.
A4: Premium Content Legal Research
A5: This stage addresses the treatments for the products in each of the 27 states.
A7: Premium Contnet Sytem Entry
A8: This stage addresses getting the rules into Determination and a strategy for management.
A10: Premium Content SSAE-16 Review
A11: This is the total time for the peer review, senior review and manager review for all of the states in the project.
